Workbook

Sheet CATALOGO
A1: NOME_PAIS | B1: ABREV_PAIS | C1: ID_PAIS | D1: IDENTIFICADOR | E1: PRIMEIRO_ANO_MANDATO | F1: NOME_LIDER | G1: TITULO_LIDER | H1: FLAG_POPULISMO_FST2022 | I1: FLAG_POPULISMO_KM2020 | J1: FLAG_POPULISMO_MS2021 | K1: FLAG_POPULISMO_GPD2022 | L1: FLAG_POPULISMO_ED2019 | M1: QTD_OBS_VALIDA | N1: PONTUACAO_VALIDA | O1: FLAG_POPULISMO_FINAL | P1: ACESSO_EM | Q1: LINGUA_ORIGINAL | R1: FONTE | S1: NOME_ARQUIVO_ORIGINAL | T1: PRIMEIRO_NOME | U1: ULTIMO_NOME | V1: REFERENCIA
A2: Argentina | B2: ARG | C2: 37 | D2: 1 | E2: 2003 | F2: Néstor Carlos Kirchner Ostoic | G2: President | H2: 1 | I2: 1 | J2: 1 | K2: 0 | L2: 1 | M2: =COUNTIF(H2:L2,"<>9") -> 5 | N2: =SUMIF(H2:L2,"<>9") -> 4 | O2: =IFERROR(ROUND(N2/M2,0),9) -> 1 | P2: 45633 | Q2: ESPANHOL | R2: https://www.cfkargentina.com/discurso-de-asuncion-del-presidente-nestor-kirchner-a-la-asamblea-legislativa-el-25-de-mayo-del-2003/ | S2: ARG_NESTOR_KIRCHNER_1.txt | T2: =_xlfn.TEXTBEFORE(F2," ") -> Néstor | U2: =_xlfn.TEXTAFTER(F2," ",LEN(F2)-LEN(SUBSTITUTE(F2," ",""))) -> Ostoic | V2: =IF(Q2="","",_xlfn.CONCAT(UPPER(U2),", ",T2,". Disponível em <",R2,">. Acesso em ",TEXT(P2,"dd ""de"" mmmm ""de"" aaaa"),".")) -> OSTOIC, Néstor. Disponível em <https://www.cfkargentina.com/discurso-de-asuncion-del-presidente-nestor-kirchner-a-la-asamblea-legislativa-el-25-de-mayo-del-2003/>. Acesso em 07 de dezembro de 2024.
A3: Argentina | B3: ARG | C3: 37 | D3: 1 | E3: 2007 | F3: Cristina Fernández de Kirchner | G3: President | H3: 1 | I3: 1 | J3: 1 | K3: 0 | L3: 1 | M3: =COUNTIF(H3:L3,"<>9") -> 5 | N3: =SUMIF(H3:L3,"<>9") -> 4 | O3: =IFERROR(ROUND(N3/M3,0),9) -> 1 | P3: 45633 | Q3: ESPANHOL | R3: https://www.casarosada.gob.ar/informacion/archivo/16462-blank-35472369 | S3: ARG_CRISTINA_KIRCHNER_1.txt | T3: =_xlfn.TEXTBEFORE(F3," ") -> Cristina | U3: =_xlfn.TEXTAFTER(F3," ",LEN(F3)-LEN(SUBSTITUTE(F3," ",""))) -> Kirchner | V3: =IF(Q3="","",_xlfn.CONCAT(UPPER(U3),", ",T3,". Disponível em <",R3,">. Acesso em ",TEXT(P3,"dd ""de"" mmmm ""de"" aaaa"),".")) -> KIRCHNER, Cristina. Disponível em <https://www.casarosada.gob.ar/informacion/archivo/16462-blank-35472369>. Acesso em 07 de dezembro de 2024.
A4: Argentina | B4: ARG | C4: 37 | D4: 2 | E4: 2011 | F4: Cristina Fernández de Kirchner | G4: President | H4: 1 | I4: 1 | J4: 1 | K4: 0 | L4: 1 | M4: =COUNTIF(H4:L4,"<>9") -> 5 | N4: =SUMIF(H4:L4,"<>9") -> 4 | O4: =IFERROR(ROUND(N4/M4,0),9) -> 1 | P4: 45633 | Q4: ESPANHOL | R4: https://www.casarosada.gob.ar/informacion/archivo/25601-acto-de-asuncion-de-mando-en-el-congreso-de-la-nacion-discurso-de-la-presidenta-de-la-nacion | S4: ARG_CRISTINA_KIRCHNER_2.txt | T4: =_xlfn.TEXTBEFORE(F4," ") -> Cristina | U4: =_xlfn.TEXTAFTER(F4," ",LEN(F4)-LEN(SUBSTITUTE(F4," ",""))) -> Kirchner | V4: =IF(Q4="","",_xlfn.CONCAT(UPPER(U4),", ",T4,". Disponível em <",R4,">. Acesso em ",TEXT(P4,"dd ""de"" mmmm ""de"" aaaa"),".")) -> KIRCHNER, Cristina. Disponível em <https://www.casarosada.gob.ar/informacion/archivo/25601-acto-de-asuncion-de-mando-en-el-congreso-de-la-nacion-discurso-de-la-presidenta-de-la-nacion>. Acesso em 07 de dezembro de 2024.
A5: Argentina | B5: ARG | C5: 37 | D5: 1 | E5: 2015 | F5: Mauricio Macri | G5: President | H5: 0 | I5: 0 | J5: 0 | K5: 0 | L5: 0 | M5: =COUNTIF(H5:L5,"<>9") -> 5 | N5: =SUMIF(H5:L5,"<>9") -> 0 | O5: =IFERROR(ROUND(N5/M5,0),9) -> 0 | P5: 45633 | Q5: ESPANHOL | R5: https://www.casarosada.gob.ar/informacion/discursos/35023-palabras-del-presidente-de-la-nacion-mauricio-macri-ante-la-asamblea-legislativa-en-el-congreso-de-la-nacion | S5: ARG_MAURICIO_MACRI_1.txt | T5: =_xlfn.TEXTBEFORE(F5," ") -> Mauricio | U5: =_xlfn.TEXTAFTER(F5," ",LEN(F5)-LEN(SUBSTITUTE(F5," ",""))) -> Macri | V5: =IF(Q5="","",_xlfn.CONCAT(UPPER(U5),", ",T5,". Disponível em <",R5,">. Acesso em ",TEXT(P5,"dd ""de"" mmmm ""de"" aaaa"),".")) -> MACRI, Mauricio. Disponível em <https://www.casarosada.gob.ar/informacion/discursos/35023-palabras-del-presidente-de-la-nacion-mauricio-macri-ante-la-asamblea-legislativa-en-el-congreso-de-la-nacion>. Acesso em 07 de dezembro de 2024.
A6: Argentina | B6: ARG | C6: 37 | D6: 1 | E6: 2019 | F6: Alberto Fernández | G6: President | H6: 0 | I6: 0 | J6: 0 | K6: 0 | L6: 9 | M6: =COUNTIF(H6:L6,"<>9") -> 4 | N6: =SUMIF(H6:L6,"<>9") -> 0 | O6: =IFERROR(ROUND(N6/M6,0),9) -> 0 | P6: 45633 | Q6: ESPANHOL | R6: https://www.casarosada.gob.ar/informacion/discursos/46596-palabras-del-presidente-alberto-fernandez-en-su-acto-de-asuncion-ante-la-asamblea-legislativa | S6: ARG_ALBERTO_FERNANDEZ_1.txt | T6: =_xlfn.TEXTBEFORE(F6," ") -> Alberto | U6: =_xlfn.TEXTAFTER(F6," ",LEN(F6)-LEN(SUBSTITUTE(F6," ",""))) -> Fernández | V6: =IF(Q6="","",_xlfn.CONCAT(UPPER(U6),", ",T6,". Disponível em <",R6,">. Acesso em ",TEXT(P6,"dd ""de"" mmmm ""de"" aaaa"),".")) -> FERNÁNDEZ, Alberto. Disponível em <https://www.casarosada.gob.ar/informacion/discursos/46596-palabras-del-presidente-alberto-fernandez-en-su-acto-de-asuncion-ante-la-asamblea-legislativa>. Acesso em 07 de dezembro de 2024.
A7: Argentina | B7: ARG | C7: 37 | D7: 1 | E7: 2023 | F7: Javier Gerardo Milei | G7: President | H7: 9 | I7: 9 | J7: 9 | K7: 9 | L7: 9 | M7: =COUNTIF(H7:L7,"<>9") -> 0 | N7: =SUMIF(H7:L7,"<>9") -> 0 | O7: =IFERROR(ROUND(N7/M7,0),9) -> 9 | P7: 45633 | Q7: ESPANHOL | R7: https://www3.hcdn.gob.ar/dependencias/prensa/archivos/discursoasuncionmilei.pdf | S7: ARG_JAVIER_MILEI_1.txt | T7: =_xlfn.TEXTBEFORE(F7," ") -> Javier | U7: =_xlfn.TEXTAFTER(F7," ",LEN(F7)-LEN(SUBSTITUTE(F7," ",""))) -> Milei | V7: =IF(Q7="","",_xlfn.CONCAT(UPPER(U7),", ",T7,". Disponível em <",R7,">. Acesso em ",TEXT(P7,"dd ""de"" mmmm ""de"" aaaa"),".")) -> MILEI, Javier. Disponível em <https://www3.hcdn.gob.ar/dependencias/prensa/archivos/discursoasuncionmilei.pdf>. Acesso em 07 de dezembro de 2024.
A8: Bolivia | B8: BOL | C8: 25 | D8: 1 | E8: 2002 | F8: Gonzalo Sánchez de Lozada Sánchez Bustamante | G8: President | H8: 0 | I8: 0 | J8: 0 | K8: 0 | L8: 0 | M8: =COUNTIF(H8:L8,"<>9") -> 5 | N8: =SUMIF(H8:L8,"<>9") -> 0 | O8: =IFERROR(ROUND(N8/M8,0),9) -> 0 | T8: =_xlfn.TEXTBEFORE(F8," ") -> Gonzalo | U8: =_xlfn.TEXTAFTER(F8," ",LEN(F8)-LEN(SUBSTITUTE(F8," ",""))) -> Bustamante | V8: =IF(Q8="","",_xlfn.CONCAT(UPPER(U8),", ",T8,". Disponível em <",R8,">. Acesso em ",TEXT(P8,"dd ""de"" mmmm ""de"" aaaa"),"."))
A9: Bolivia | B9: BOL | C9: 25 | D9: 1 | E9: 2005 | F9: Enrique Eduardo Rodríguez Veltzé | G9: President | H9: 0 | I9: 0 | J9: 0 | K9: 0 | L9: 0 | M9: =COUNTIF(H9:L9,"<>9") -> 5 | N9: =SUMIF(H9:L9,"<>9") -> 0 | O9: =IFERROR(ROUND(N9/M9,0),9) -> 0 | P9: 45633 | Q9: ESPANHOL | R9: https://reliefweb.int/report/bolivia/discurso-de-eduardo-rodriguez-veltze-tras-su-posesion-como-presidente-constitucional | S9: BOL_ENRIQUE_VELTZE_1.txt | T9: =_xlfn.TEXTBEFORE(F9," ") -> Enrique | U9: =_xlfn.TEXTAFTER(F9," ",LEN(F9)-LEN(SUBSTITUTE(F9," ",""))) -> Veltzé | V9: =IF(Q9="","",_xlfn.CONCAT(UPPER(U9),", ",T9,". Disponível em <",R9,">. Acesso em ",TEXT(P9,"dd ""de"" mmmm ""de"" aaaa"),".")) -> VELTZÉ, Enrique. Disponível em <https://reliefweb.int/report/bolivia/discurso-de-eduardo-rodriguez-veltze-tras-su-posesion-como-presidente-constitucional>. Acesso em 07 de dezembro de 2024.
A10: Bolivia | B10: BOL | C10: 25 | D10: 1 | E10: 2006 | F10: Juan Evo Morales Ayma | G10: President of the Plurinational State | H10: 1 | I10: 1 | J10: 1 | K10: 1 | L10: 1 | M10: =COUNTIF(H10:L10,"<>9") -> 5 | N10: =SUMIF(H10:L10,"<>9") -> 5 | O10: =IFERROR(ROUND(N10/M10,0),9) -> 1 | P10: 45634 | Q10: ESPANHOL | R10: https://www.pagina12.com.ar/diario/especiales/18-62330-2006-01-30.html | S10: BOL_EVO_MORALES_1.txt | T10: =_xlfn.TEXTBEFORE(F10," ") -> Juan | U10: =_xlfn.TEXTAFTER(F10," ",LEN(F10)-LEN(SUBSTITUTE(F10," ",""))) -> Ayma | V10: =IF(Q10="","",_xlfn.CONCAT(UPPER(U10),", ",T10,". Disponível em <",R10,">. Acesso em ",TEXT(P10,"dd ""de"" mmmm ""de"" aaaa"),".")) -> AYMA, Juan. Disponível em <https://www.pagina12.com.ar/diario/especiales/18-62330-2006-01-30.html>. Acesso em 08 de dezembro de 2024.
A11: Bolivia | B11: BOL | C11: 25 | D11: 2 | E11: 2010 | F11: Juan Evo Morales Ayma | G11: President of the Plurinational State | H11: 1 | I11: 1 | J11: 1 | K11: 1 | L11: 1 | M11: =COUNTIF(H11:L11,"<>9") -> 5 | N11: =SUMIF(H11:L11,"<>9") -> 5 | O11: =IFERROR(ROUND(N11/M11,0),9) -> 1 | P11: 45724 | Q11: ESPANHOL | R11: https://www.somossur.net/documentos/II_22012015_EVOMORALES_POSESION_ASAMBLEALEGISLATIVA.pdf | S11: BOL_EVO_MORALES_2.txt | T11: =_xlfn.TEXTBEFORE(F11," ") -> Juan | U11: =_xlfn.TEXTAFTER(F11," ",LEN(F11)-LEN(SUBSTITUTE(F11," ",""))) -> Ayma | V11: =IF(Q11="","",_xlfn.CONCAT(UPPER(U11),", ",T11,". Disponível em <",R11,">. Acesso em ",TEXT(P11,"dd ""de"" mmmm ""de"" aaaa"),".")) -> AYMA, Juan. Disponível em <https://www.somossur.net/documentos/II_22012015_EVOMORALES_POSESION_ASAMBLEALEGISLATIVA.pdf>. Acesso em 08 de março de 2025.
A12: Bolivia | B12: BOL | C12: 25 | D12: 3 | E12: 2015 | F12: Juan Evo Morales Ayma | G12: President of the Plurinational State | H12: 1 | I12: 1 | J12: 1 | K12: 1 | L12: 1 | M12: =COUNTIF(H12:L12,"<>9") -> 5 | N12: =SUMIF(H12:L12,"<>9") -> 5 | O12: =IFERROR(ROUND(N12/M12,0),9) -> 1 | P12: 45724 | Q12: ESPANHOL | R12: https://www.youtube.com/watch?v=b6BpJz2XDIY | S12: BOL_EVO_MORALES_3.txt | T12: =_xlfn.TEXTBEFORE(F12," ") -> Juan | U12: =_xlfn.TEXTAFTER(F12," ",LEN(F12)-LEN(SUBSTITUTE(F12," ",""))) -> Ayma | V12: =IF(Q12="","",_xlfn.CONCAT(UPPER(U12),", ",T12,". Disponível em <",R12,">. Acesso em ",TEXT(P12,"dd ""de"" mmmm ""de"" aaaa"),".")) -> AYMA, Juan. Disponível em <https://www.youtube.com/watch?v=b6BpJz2XDIY>. Acesso em 08 de março de 2025.
A13: Bolivia | B13: BOL | C13: 25 | D13: 1 | E13: 2019 | F13: Jeanine Áñez Chávez | G13: President of the Plurinational State | H13: 0 | I13: 0 | J13: 0 | K13: 0 | L13: 9 | M13: =COUNTIF(H13:L13,"<>9") -> 4 | N13: =SUMIF(H13:L13,"<>9") -> 0 | O13: =IFERROR(ROUND(N13/M13,0),9) -> 0 | P13: 45634 | Q13: ESPANHOL | R13: https://embolnic.com/2019/11/15/discurso-de-la-ministra-de-relaciones-exteriores-en-la-posesion-de-los-ministros-de-s-e-la-presidenta-constitucional-del-estado-plurinacional-de-bolivia-jeanine-anez-chavez/ | S13: BOL_JEANINE_CHAVEZ_1.txt | T13: =_xlfn.TEXTBEFORE(F13," ") -> Jeanine | U13: =_xlfn.TEXTAFTER(F13," ",LEN(F13)-LEN(SUBSTITUTE(F13," ",""))) -> Chávez | V13: =IF(Q13="","",_xlfn.CONCAT(UPPER(U13),", ",T13,". Disponível em <",R13,">. Acesso em ",TEXT(P13,"dd ""de"" mmmm ""de"" aaaa"),".")) -> CHÁVEZ, Jeanine. Disponível em <https://embolnic.com/2019/11/15/discurso-de-la-ministra-de-relaciones-exteriores-en-la-posesion-de-los-ministros-de-s-e-la-presidenta-constitucional-del-estado-plurinacional-de-bolivia-jeanine-anez-chavez/>. Acesso em 08 de dezembro de 2024.
A14: Bolivia | B14: BOL | C14: 25 | D14: 1 | E14: 2020 | F14: Luis Alberto Arce Catacora | G14: President of the Plurinational State | H14: 0 | I14: 9 | J14: 9 | K14: 0 | L14: 9 | M14: =COUNTIF(H14:L14,"<>9") -> 2 | N14: =SUMIF(H14:L14,"<>9") -> 0 | O14: =IFERROR(ROUND(N14/M14,0),9) -> 0 | P14: 45634 | Q14: ESPANHOL | R14: https://www.laondadigital.com.uy/archivos/48126 | S14: BOL_LUIS_ARCE_1.txt | T14: =_xlfn.TEXTBEFORE(F14," ") -> Luis | U14: =_xlfn.TEXTAFTER(F14," ",LEN(F14)-LEN(SUBSTITUTE(F14," ",""))) -> Catacora | V14: =IF(Q14="","",_xlfn.CONCAT(UPPER(U14),", ",T14,". Disponível em <",R14,">. Acesso em ",TEXT(P14,"dd ""de"" mmmm ""de"" aaaa"),".")) -> CATACORA, Luis. Disponível em <https://www.laondadigital.com.uy/archivos/48126>. Acesso em 08 de dezembro de 2024.
A15: Brazil | B15: BRA | C15: 19 | D15: 1 | E15: 2003 | F15: Luiz Inácio Lula da Silva | G15: President | H15: 0 | I15: 0 | J15: 9 | K15: 0 | L15: 0 | M15: =COUNTIF(H15:L15,"<>9") -> 4 | N15: =SUMIF(H15:L15,"<>9") -> 0 | O15: =IFERROR(ROUND(N15/M15,0),9) -> 0 | P15: 45633 | Q15: PORTUGUES | R15: https://www.biblioteca.presidencia.gov.br/presidencia/ex-presidentes/luiz-inacio-lula-da-silva/discursos/1o-mandato/2003/01-01-pronunciamento-a-nacao-do-presidente-da-republica-luiz-inacio-lula-da-silva-apos-a-cerimonia-de-posse.pdf/view | S15: BRA_LUIZ_INACIO_1.txt | T15: =_xlfn.TEXTBEFORE(F15," ") -> Luiz | U15: =_xlfn.TEXTAFTER(F15," ",LEN(F15)-LEN(SUBSTITUTE(F15," ",""))) -> Silva | V15: =IF(Q15="","",_xlfn.CONCAT(UPPER(U15),", ",T15,". Disponível em <",R15,">. Acesso em ",TEXT(P15,"dd ""de"" mmmm ""de"" aaaa"),".")) -> SILVA, Luiz. Disponível em <https://www.biblioteca.presidencia.gov.br/presidencia/ex-presidentes/luiz-inacio-lula-da-silva/discursos/1o-mandato/2003/01-01-pronunciamento-a-nacao-do-presidente-da-republica-luiz-inacio-lula-da-silva-apos-a-cerimonia-de-posse.pdf/view>. Acesso em 07 de dezembro de 2024.
A16: Brazil | B16: BRA | C16: 19 | D16: 2 | E16: 2007 | F16: Luiz Inácio Lula da Silva | G16: President | H16: 0 | I16: 0 | J16: 9 | K16: 0 | L16: 0 | M16: =COUNTIF(H16:L16,"<>9") -> 4 | N16: =SUMIF(H16:L16,"<>9") -> 0 | O16: =IFERROR(ROUND(N16/M16,0),9) -> 0 | P16: 45634 | Q16: PORTUGUES | R16: https://www.biblioteca.presidencia.gov.br/presidencia/ex-presidentes/luiz-inacio-lula-da-silva/discursos/2o-mandato/2007/01-01-2007-pronunciamento-a-nacao-do-presidente-da-republica-luiz-inacio-lula-da-silva-na-cerimonia-de-posse/view | S16: BRA_LUIZ_INACIO_2.txt | T16: =_xlfn.TEXTBEFORE(F16," ") -> Luiz | U16: =_xlfn.TEXTAFTER(F16," ",LEN(F16)-LEN(SUBSTITUTE(F16," ",""))) -> Silva | V16: =IF(Q16="","",_xlfn.CONCAT(UPPER(U16),", ",T16,". Disponível em <",R16,">. Acesso em ",TEXT(P16,"dd ""de"" mmmm ""de"" aaaa"),".")) -> SILVA, Luiz. Disponível em <https://www.biblioteca.presidencia.gov.br/presidencia/ex-presidentes/luiz-inacio-lula-da-silva/discursos/2o-mandato/2007/01-01-2007-pronunciamento-a-nacao-do-presidente-da-republica-luiz-inacio-lula-da-silva-na-cerimonia-de-posse/view>. Acesso em 08 de dezembro de 2024.
A17: Brazil | B17: BRA | C17: 19 | D17: 1 | E17: 2011 | F17: Dilma Vana Rousseff | G17: President | H17: 0 | I17: 0 | J17: 9 | K17: 0 | L17: 0 | M17: =COUNTIF(H17:L17,"<>9") -> 4 | N17: =SUMIF(H17:L17,"<>9") -> 0 | O17: =IFERROR(ROUND(N17/M17,0),9) -> 0 | P17: 45634 | Q17: PORTUGUES | R17: https://www.biblioteca.presidencia.gov.br/presidencia/ex-presidentes/dilma-rousseff/discursos/discursos-da-presidenta/discurso-da-presidenta-da-republica-dilma-rousseff-durante-compromisso-constitucional-perante-o-congresso-nacional | S17: BRA_DILMA_ROUSSEFF_1.txt | T17: =_xlfn.TEXTBEFORE(F17," ") -> Dilma | U17: =_xlfn.TEXTAFTER(F17," ",LEN(F17)-LEN(SUBSTITUTE(F17," ",""))) -> Rousseff | V17: =IF(Q17="","",_xlfn.CONCAT(UPPER(U17),", ",T17,". Disponível em <",R17,">. Acesso em ",TEXT(P17,"dd ""de"" mmmm ""de"" aaaa"),".")) -> ROUSSEFF, Dilma. Disponível em <https://www.biblioteca.presidencia.gov.br/presidencia/ex-presidentes/dilma-rousseff/discursos/discursos-da-presidenta/discurso-da-presidenta-da-republica-dilma-rousseff-durante-compromisso-constitucional-perante-o-congresso-nacional>. Acesso em 08 de dezembro de 2024.
A18: Brazil | B18: BRA | C18: 19 | D18: 3 | E18: 2015 | F18: Dilma Vana Rousseff | G18: President | H18: 0 | I18: 0 | J18: 9 | K18: 0 | L18: 0 | M18: =COUNTIF(H18:L18,"<>9") -> 4 | N18: =SUMIF(H18:L18,"<>9") -> 0 | O18: =IFERROR(ROUND(N18/M18,0),9) -> 0 | P18: 45634 | Q18: PORTUGUES | R18: https://www.biblioteca.presidencia.gov.br/presidencia/ex-presidentes/dilma-rousseff/discursos/discursos-da-presidenta/discurso-da-presidenta-da-republica-dilma-rousseff-durante-compromisso-constitucional-perante-o-congresso-nacional-1 | S18: BRA_DILMA_ROUSSEFF_2.txt | T18: =_xlfn.TEXTBEFORE(F18," ") -> Dilma | U18: =_xlfn.TEXTAFTER(F18," ",LEN(F18)-LEN(SUBSTITUTE(F18," ",""))) -> Rousseff | V18: =IF(Q18="","",_xlfn.CONCAT(UPPER(U18),", ",T18,". Disponível em <",R18,">. Acesso em ",TEXT(P18,"dd ""de"" mmmm ""de"" aaaa"),".")) -> ROUSSEFF, Dilma. Disponível em <https://www.biblioteca.presidencia.gov.br/presidencia/ex-presidentes/dilma-rousseff/discursos/discursos-da-presidenta/discurso-da-presidenta-da-republica-dilma-rousseff-durante-compromisso-constitucional-perante-o-congresso-nacional-1>. Acesso em 08 de dezembro de 2024.
A19: Brazil | B19: BRA | C19: 19 | D19: 1 | E19: 2016 | F19: Michel Miguel Elias Temer Lulia | G19: President | H19: 0 | I19: 0 | J19: 9 | K19: 0 | L19: 0 | M19: =COUNTIF(H19:L19,"<>9") -> 4 | N19: =SUMIF(H19:L19,"<>9") -> 0 | O19: =IFERROR(ROUND(N19/M19,0),9) -> 0 | P19: 45634 | Q19: PORTUGUES | R19: https://www.biblioteca.presidencia.gov.br/presidencia/ex-presidentes/michel-temer/discursos-do-presidente-da-republica/discurso-do-presidente-da-republica-michel-temer-durante-cerimonia-de-posse-dos-novos-ministros-de-estado-palacio-do-planalto | S19: BRA_MICHEL_TEMER_1.txt | T19: =_xlfn.TEXTBEFORE(F19," ") -> Michel | U19: =_xlfn.TEXTAFTER(F19," ",LEN(F19)-LEN(SUBSTITUTE(F19," ",""))) -> Lulia | V19: =IF(Q19="","",_xlfn.CONCAT(UPPER(U19),", ",T19,". Disponível em <",R19,">. Acesso em ",TEXT(P19,"dd ""de"" mmmm ""de"" aaaa"),".")) -> LULIA, Michel. Disponível em <https://www.biblioteca.presidencia.gov.br/presidencia/ex-presidentes/michel-temer/discursos-do-presidente-da-republica/discurso-do-presidente-da-republica-michel-temer-durante-cerimonia-de-posse-dos-novos-ministros-de-estado-palacio-do-planalto>. Acesso em 08 de dezembro de 2024.
A20: Brazil | B20: BRA | C20: 19 | D20: 1 | E20: 2019 | F20: Jair Messias Bolsonaro | G20: President | H20: 1 | I20: 1 | J20: 9 | K20: 0 | L20: 1 | M20: =COUNTIF(H20:L20,"<>9") -> 4 | N20: =SUMIF(H20:L20,"<>9") -> 3 | O20: =IFERROR(ROUND(N20/M20,0),9) -> 1 | P20: 45634 | Q20: PORTUGUES | R20: https://www.biblioteca.presidencia.gov.br/presidencia/ex-presidentes/bolsonaro/discursos/discurso-do-presidente-da-republica-jair-bolsonaro-durante-cerimonia-de-posse-no-congresso-nacional | S20: BRA_JAIR_BOLSONARO_1.txt | T20: =_xlfn.TEXTBEFORE(F20," ") -> Jair | U20: =_xlfn.TEXTAFTER(F20," ",LEN(F20)-LEN(SUBSTITUTE(F20," ",""))) -> Bolsonaro | V20: =IF(Q20="","",_xlfn.CONCAT(UPPER(U20),", ",T20,". Disponível em <",R20,">. Acesso em ",TEXT(P20,"dd ""de"" mmmm ""de"" aaaa"),".")) -> BOLSONARO, Jair. Disponível em <https://www.biblioteca.presidencia.gov.br/presidencia/ex-presidentes/bolsonaro/discursos/discurso-do-presidente-da-republica-jair-bolsonaro-durante-cerimonia-de-posse-no-congresso-nacional>. Acesso em 08 de dezembro de 2024.
... A44: Dominican Republic | B44: DOM | C44: 114 | D44: 1 | E44: 2020 | F44: Luis Rodolfo Abinader | G44: President | H44: 9 | I44: 9 | J44: 9 | K44: 0 | L44: 9 | M44: =COUNTIF(H44:L44,"<>9") -> 1 | N44: =SUMIF(H44:L44,"<>9") -> 0 | O44: =IFERROR(ROUND(N44/M44,0),9) -> 0 | P44: 45641 | Q44: ESPANHOL | R44: https://presidencia.gob.do/discursos/discurso-del-presidente-luis-abinader-en-el-acto-de-toma-de-posesion-ante-la-asamblea | S44: DOM_LUIS_ABINADER_1.txt | T44: =_xlfn.TEXTBEFORE(F44," ") -> Luis | U44: =_xlfn.TEXTAFTER(F44," ",LEN(F44)-LEN(SUBSTITUTE(F44," ",""))) -> Abinader | V44: =IF(Q44="","",_xlfn.CONCAT(UPPER(U44),", ",T44,". Disponível em <",R44,">. Acesso em ",TEXT(P44,"dd ""de"" mmmm ""de"" aaaa"),".")) -> ABINADER, Luis. Disponível em <https://presidencia.gob.do/discursos/discurso-del-presidente-luis-abinader-en-el-acto-de-toma-de-posesion-ante-la-asamblea>. Acesso em 15 de dezembro de 2024.
A45: Ecuador | B45: ECU | C45: 75 | D45: 1 | E45: 2000 | F45: Gustavo José Joaquín Noboa Bejarano | G45: President | H45: 0 | I45: 0 | J45: 0 | K45: 0 | L45: 0 | M45: =COUNTIF(H45:L45,"<>9") -> 5 | N45: =SUMIF(H45:L45,"<>9") -> 0 | O45: =IFERROR(ROUND(N45/M45,0),9) -> 0 | T45: =_xlfn.TEXTBEFORE(F45," ") -> Gustavo | U45: =_xlfn.TEXTAFTER(F45," ",LEN(F45)-LEN(SUBSTITUTE(F45," ",""))) -> Bejarano | V45: =IF(Q45="","",_xlfn.CONCAT(UPPER(U45),", ",T45,". Disponível em <",R45,">. Acesso em ",TEXT(P45,"dd ""de"" mmmm ""de"" aaaa"),"."))
A46: Ecuador | B46: ECU | C46: 75 | D46: 1 | E46: 2003 | F46: Lucio Edwin Gutiérrez Borbúa | G46: President | H46: 1 | I46: 1 | J46: 0 | K46: 1 | L46: 0 | M46: =COUNTIF(H46:L46,"<>9") -> 5 | N46: =SUMIF(H46:L46,"<>9") -> 3 | O46: =IFERROR(ROUND(N46/M46,0),9) -> 1 | P46: 45724 | Q46: ESPANHOL | R46: http://www.llacta.org/organiz/coms/com232.htm | S46: ECU_LUCIO_GUTIERREZ_1.txt | T46: =_xlfn.TEXTBEFORE(F46," ") -> Lucio | U46: =_xlfn.TEXTAFTER(F46," ",LEN(F46)-LEN(SUBSTITUTE(F46," ",""))) -> Borbúa | V46: =IF(Q46="","",_xlfn.CONCAT(UPPER(U46),", ",T46,". Disponível em <",R46,">. Acesso em ",TEXT(P46,"dd ""de"" mmmm ""de"" aaaa"),".")) -> BORBÚA, Lucio. Disponível em <http://www.llacta.org/organiz/coms/com232.htm>. Acesso em 08 de março de 2025.
A47: Ecuador | B47: ECU | C47: 75 | D47: 1 | E47: 2005 | F47: Luis Alfredo Palacio González | G47: President | H47: 0 | I47: 0 | J47: 0 | K47: 0 | L47: 0 | M47: =COUNTIF(H47:L47,"<>9") -> 5 | N47: =SUMIF(H47:L47,"<>9") -> 0 | O47: =IFERROR(ROUND(N47/M47,0),9) -> 0 | T47: =_xlfn.TEXTBEFORE(F47," ") -> Luis | U47: =_xlfn.TEXTAFTER(F47," ",LEN(F47)-LEN(SUBSTITUTE(F47," ",""))) -> González | V47: =IF(Q47="","",_xlfn.CONCAT(UPPER(U47),", ",T47,". Disponível em <",R47,">. Acesso em ",TEXT(P47,"dd ""de"" mmmm ""de"" aaaa"),"."))
A48: Ecuador | B48: ECU | C48: 75 | D48: 1 | E48: 2007 | F48: Rafael Vicente Correa Delgado | G48: President | H48: 1 | I48: 1 | J48: 1 | K48: 1 | L48: 1 | M48: =COUNTIF(H48:L48,"<>9") -> 5 | N48: =SUMIF(H48:L48,"<>9") -> 5 | O48: =IFERROR(ROUND(N48/M48,0),9) -> 1 | P48: 45641 | Q48: ESPANHOL | R48: https://www.presidencia.gob.ec/wp-content/uploads/downloads/2015/07/Posesion-Presidente-2007.pdf | S48: ECU_RAFAEL_CORREA_1.txt | T48: =_xlfn.TEXTBEFORE(F48," ") -> Rafael | U48: =_xlfn.TEXTAFTER(F48," ",LEN(F48)-LEN(SUBSTITUTE(F48," ",""))) -> Delgado | V48: =IF(Q48="","",_xlfn.CONCAT(UPPER(U48),", ",T48,". Disponível em <",R48,">. Acesso em ",TEXT(P48,"dd ""de"" mmmm ""de"" aaaa"),".")) -> DELGADO, Rafael. Disponível em <https://www.presidencia.gob.ec/wp-content/uploads/downloads/2015/07/Posesion-Presidente-2007.pdf>. Acesso em 15 de dezembro de 2024.
A49: Ecuador | B49: ECU | C49: 75 | D49: 2 | E49: 2009 | F49: Rafael Vicente Correa Delgado | G49: President | H49: 1 | I49: 1 | J49: 1 | K49: 1 | L49: 1 | M49: =COUNTIF(H49:L49,"<>9") -> 5 | N49: =SUMIF(H49:L49,"<>9") -> 5 | O49: =IFERROR(ROUND(N49/M49,0),9) -> 1 | P49: 45641 | Q49: ESPANHOL | R49: https://www.presidencia.gob.ec/wp-content/uploads/downloads/2013/10/10-10-09-Discurso_posesion_Presidencial.pdf | S49: ECU_RAFAEL_CORREA_2.txt | T49: =_xlfn.TEXTBEFORE(F49," ") -> Rafael | U49: =_xlfn.TEXTAFTER(F49," ",LEN(F49)-LEN(SUBSTITUTE(F49," ",""))) -> Delgado | V49: =IF(Q49="","",_xlfn.CONCAT(UPPER(U49),", ",T49,". Disponível em <",R49,">. Acesso em ",TEXT(P49,"dd ""de"" mmmm ""de"" aaaa"),".")) -> DELGADO, Rafael. Disponível em <https://www.presidencia.gob.ec/wp-content/uploads/downloads/2013/10/10-10-09-Discurso_posesion_Presidencial.pdf>. Acesso em 15 de dezembro de 2024.
A50: Ecuador | B50: ECU | C50: 75 | D50: 3 | E50: 2013 | F50: Rafael Vicente Correa Delgado | G50: President | H50: 1 | I50: 1 | J50: 1 | K50: 1 | L50: 1 | M50: =COUNTIF(H50:L50,"<>9") -> 5 | N50: =SUMIF(H50:L50,"<>9") -> 5 | O50: =IFERROR(ROUND(N50/M50,0),9) -> 1 | P50: 45641 | Q50: ESPANHOL | R50: https://www.youtube.com/watch?v=N0X9rDrO0ik | S50: ECU_RAFAEL_CORREA_3.txt | T50: =_xlfn.TEXTBEFORE(F50," ") -> Rafael | U50: =_xlfn.TEXTAFTER(F50," ",LEN(F50)-LEN(SUBSTITUTE(F50," ",""))) -> Delgado | V50: =IF(Q50="","",_xlfn.CONCAT(UPPER(U50),", ",T50,". Disponível em <",R50,">. Acesso em ",TEXT(P50,"dd ""de"" mmmm ""de"" aaaa"),".")) -> DELGADO, Rafael. Disponível em <https://www.youtube.com/watch?v=N0X9rDrO0ik>. Acesso em 15 de dezembro de 2024.
A51: Ecuador | B51: ECU | C51: 75 | D51: 1 | E51: 2017 | F51: Lenín Boltaire Moreno Garcés | G51: President | H51: 0 | I51: 0 | J51: 0 | K51: 0 | L51: 0 | M51: =COUNTIF(H51:L51,"<>9") -> 5 | N51: =SUMIF(H51:L51,"<>9") -> 0 | O51: =IFERROR(ROUND(N51/M51,0),9) -> 0 | P51: 45641 | Q51: ESPANHOL | R51: https://www.presidencia.gob.ec/wp-content/uploads/downloads/2017/06/2017.05.24-DISCURSO-POSESI%C3%93N-ANTE-LA-ASAMBLEA-NACIONAL.pdf | S51: ECU_LENIN_MORENO_1.txt | T51: =_xlfn.TEXTBEFORE(F51," ") -> Lenín | U51: =_xlfn.TEXTAFTER(F51," ",LEN(F51)-LEN(SUBSTITUTE(F51," ",""))) -> Garcés | V51: =IF(Q51="","",_xlfn.CONCAT(UPPER(U51),", ",T51,". Disponível em <",R51,">. Acesso em ",TEXT(P51,"dd ""de"" mmmm ""de"" aaaa"),".")) -> GARCÉS, Lenín. Disponível em <https://www.presidencia.gob.ec/wp-content/uploads/downloads/2017/06/2017.05.24-DISCURSO-POSESI%C3%93N-ANTE-LA-ASAMBLEA-NACIONAL.pdf>. Acesso em 15 de dezembro de 2024.
A52: Ecuador | B52: ECU | C52: 75 | D52: 1 | E52: 2021 | F52: Guillermo Alberto Santiago Lasso Mendoza | G52: President | H52: 9 | I52: 9 | J52: 9 | K52: 9 | L52: 9 | M52: =COUNTIF(H52:L52,"<>9") -> 0 | N52: =SUMIF(H52:L52,"<>9") -> 0 | O52: =IFERROR(ROUND(N52/M52,0),9) -> 9 | P52: 45641 | Q52: ESPANHOL | R52: https://www.presidencia.gob.ec/wp-content/uploads/downloads/2021/05/2021.05.24-POSESION-PRESIDENTE-LASSO.pdf | S52: ECU_GUILHERME_LASSO_1.txt | T52: =_xlfn.TEXTBEFORE(F52," ") -> Guillermo | U52: =_xlfn.TEXTAFTER(F52," ",LEN(F52)-LEN(SUBSTITUTE(F52," ",""))) -> Mendoza | V52: =IF(Q52="","",_xlfn.CONCAT(UPPER(U52),", ",T52,". Disponível em <",R52,">. Acesso em ",TEXT(P52,"dd ""de"" mmmm ""de"" aaaa"),".")) -> MENDOZA, Guillermo. Disponível em <https://www.presidencia.gob.ec/wp-content/uploads/downloads/2021/05/2021.05.24-POSESION-PRESIDENTE-LASSO.pdf>. Acesso em 15 de dezembro de 2024.
A53: Ecuador | B53: ECU | C53: 75 | D53: 1 | E53: 2023 | F53: Daniel Noboa | G53: President | H53: 9 | I53: 9 | J53: 9 | K53: 9 | L53: 9 | M53: =COUNTIF(H53:L53,"<>9") -> 0 | N53: =SUMIF(H53:L53,"<>9") -> 0 | O53: =IFERROR(ROUND(N53/M53,0),9) -> 9 | P53: 45641 | Q53: ESPANHOL | R53: https://www.presidencia.gob.ec/wp-content/uploads/downloads/2023/11/2023.11.23-POSESION-PRESIDENTE-DANIEL-NOBOA.pdf | S53: ECU_DANIEL_NOBOA_1.txt | T53: =_xlfn.TEXTBEFORE(F53," ") -> Daniel | U53: =_xlfn.TEXTAFTER(F53," ",LEN(F53)-LEN(SUBSTITUTE(F53," ",""))) -> Noboa | V53: =IF(Q53="","",_xlfn.CONCAT(UPPER(U53),", ",T53,". Disponível em <",R53,">. Acesso em ",TEXT(P53,"dd ""de"" mmmm ""de"" aaaa"),".")) -> NOBOA, Daniel. Disponível em <https://www.presidencia.gob.ec/wp-content/uploads/downloads/2023/11/2023.11.23-POSESION-PRESIDENTE-DANIEL-NOBOA.pdf>. Acesso em 15 de dezembro de 2024.
A54: El Salvador | B54: SLV | C54: 22 | D54: 1 | E54: 2004 | F54: Elías Antonio Saca González | G54: President | H54: 9 | I54: 9 | J54: 9 | K54: 0 | L54: 9 | M54: =COUNTIF(H54:L54,"<>9") -> 1 | N54: =SUMIF(H54:L54,"<>9") -> 0 | O54: =IFERROR(ROUND(N54/M54,0),9) -> 0 | P54: 45641 | Q54: ESPANHOL | R54: http://luiseduardoaguilarvasquez.blogspot.com/2016/05/discurso-toma-de-posesion-presidente-de.html | S54: SLV_ANTONIO_SACA_1.txt | T54: =_xlfn.TEXTBEFORE(F54," ") -> Elías | U54: =_xlfn.TEXTAFTER(F54," ",LEN(F54)-LEN(SUBSTITUTE(F54," ",""))) -> González | V54: =IF(Q54="","",_xlfn.CONCAT(UPPER(U54),", ",T54,". Disponível em <",R54,">. Acesso em ",TEXT(P54,"dd ""de"" mmmm ""de"" aaaa"),".")) -> GONZÁLEZ, Elías. Disponível em <http://luiseduardoaguilarvasquez.blogspot.com/2016/05/discurso-toma-de-posesion-presidente-de.html>. Acesso em 15 de dezembro de 2024.
A55: El Salvador | B55: SLV | C55: 22 | D55: 1 | E55: 2009 | F55: Carlos Mauricio Funes Cartagena | G55: President | H55: 9 | I55: 9 | J55: 9 | K55: 0 | L55: 9 | M55: =COUNTIF(H55:L55,"<>9") -> 1 | N55: =SUMIF(H55:L55,"<>9") -> 0 | O55: =IFERROR(ROUND(N55/M55,0),9) -> 0 | P55: 45641 | Q55: ESPANHOL | R55: http://especiales.laprensagrafica.com/2011/funes2doaniversario/wp-content/uploads/2011/05/1-Toma-de-posesi%C3%B3n-presidente-Funes.pdf | S55: SLV_MAURICIO_FUNES_1.txt | T55: =_xlfn.TEXTBEFORE(F55," ") -> Carlos | U55: =_xlfn.TEXTAFTER(F55," ",LEN(F55)-LEN(SUBSTITUTE(F55," ",""))) -> Cartagena | V55: =IF(Q55="","",_xlfn.CONCAT(UPPER(U55),", ",T55,". Disponível em <",R55,">. Acesso em ",TEXT(P55,"dd ""de"" mmmm ""de"" aaaa"),".")) -> CARTAGENA, Carlos. Disponível em <http://especiales.laprensagrafica.com/2011/funes2doaniversario/wp-content/uploads/2011/05/1-Toma-de-posesi%C3%B3n-presidente-Funes.pdf>. Acesso em 15 de dezembro de 2024.
A56: El Salvador | B56: SLV | C56: 22 | D56: 1 | E56: 2014 | F56: Salvador Sánchez Cerén | G56: President | H56: 9 | I56: 9 | J56: 9 | K56: 0 | L56: 9 | M56: =COUNTIF(H56:L56,"<>9") -> 1 | N56: =SUMIF(H56:L56,"<>9") -> 0 | O56: =IFERROR(ROUND(N56/M56,0),9) -> 0 | P56: 45724 | Q56: ESPANHOL | R56: https://www.youtube.com/watch?v=8tjYfNYpZlQ | S56: SLV_SALVADOR_CEREN_1.txt | T56: =_xlfn.TEXTBEFORE(F56," ") -> Salvador | U56: =_xlfn.TEXTAFTER(F56," ",LEN(F56)-LEN(SUBSTITUTE(F56," ",""))) -> Cerén | V56: =IF(Q56="","",_xlfn.CONCAT(UPPER(U56),", ",T56,". Disponível em <",R56,">. Acesso em ",TEXT(P56,"dd ""de"" mmmm ""de"" aaaa"),".")) -> CERÉN, Salvador. Disponível em <https://www.youtube.com/watch?v=8tjYfNYpZlQ>. Acesso em 08 de março de 2025.
A57: El Salvador | B57: SLV | C57: 22 | D57: 1 | E57: 2019 | F57: Nayib Armando Bukele Ortez | G57: President | H57: 9 | I57: 9 | J57: 9 | K57: 0 | L57: 9 | M57: =COUNTIF(H57:L57,"<>9") -> 1 | N57: =SUMIF(H57:L57,"<>9") -> 0 | O57: =IFERROR(ROUND(N57/M57,0),9) -> 0 | P57: 45641 | Q57: ESPANHOL | R57: https://www.presidencia.gob.sv/wp-content/uploads/2020/09/Toma-de-posesi%C3%B3n-01-06-2019-1.pdf | S57: SLV_NAYIB_BUKELE_1.txt | T57: =_xlfn.TEXTBEFORE(F57," ") -> Nayib | U57: =_xlfn.TEXTAFTER(F57," ",LEN(F57)-LEN(SUBSTITUTE(F57," ",""))) -> Ortez | V57: =IF(Q57="","",_xlfn.CONCAT(UPPER(U57),", ",T57,". Disponível em <",R57,">. Acesso em ",TEXT(P57,"dd ""de"" mmmm ""de"" aaaa"),".")) -> ORTEZ, Nayib. Disponível em <https://www.presidencia.gob.sv/wp-content/uploads/2020/09/Toma-de-posesi%C3%B3n-01-06-2019-1.pdf>. Acesso em 15 de dezembro de 2024.
A58: Guatemala | B58: GTM | C58: 78 | D58: 1 | E58: 2000 | F58: Alfonso Antonio Portillo Cabrera | G58: President | H58: 9 | I58: 9 | J58: 9 | K58: 0 | L58: 9 | M58: =COUNTIF(H58:L58,"<>9") -> 1 | N58: =SUMIF(H58:L58,"<>9") -> 0 | O58: =IFERROR(ROUND(N58/M58,0),9) -> 0 | P58: 45642 | Q58: ESPANHOL | R58: https://www.plazapublica.com.gt/sites/default/files/2000_alfonso_portillo.pdf | S58: GTM_ALFONSO_PORTILLO_1.txt | T58: =_xlfn.TEXTBEFORE(F58," ") -> Alfonso | U58: =_xlfn.TEXTAFTER(F58," ",LEN(F58)-LEN(SUBSTITUTE(F58," ",""))) -> Cabrera | V58: =IF(Q58="","",_xlfn.CONCAT(UPPER(U58),", ",T58,". Disponível em <",R58,">. Acesso em ",TEXT(P58,"dd ""de"" mmmm ""de"" aaaa"),".")) -> CABRERA, Alfonso. Disponível em <https://www.plazapublica.com.gt/sites/default/files/2000_alfonso_portillo.pdf>. Acesso em 16 de dezembro de 2024.
A59: Guatemala | B59: GTM | C59: 78 | D59: 1 | E59: 2004 | F59: Óscar José Rafael Berger Perdomo | G59: President | H59: 9 | I59: 9 | J59: 9 | K59: 0 | L59: 9 | M59: =COUNTIF(H59:L59,"<>9") -> 1 | N59: =SUMIF(H59:L59,"<>9") -> 0 | O59: =IFERROR(ROUND(N59/M59,0),9) -> 0 | P59: 45642 | Q59: ESPANHOL | R59: https://www.plazapublica.com.gt/sites/default/files/2004_oscar_berger.pdf | S59: GTM_OSCAR_BERGER_1.txt | T59: =_xlfn.TEXTBEFORE(F59," ") -> Óscar | U59: =_xlfn.TEXTAFTER(F59," ",LEN(F59)-LEN(SUBSTITUTE(F59," ",""))) -> Perdomo | V59: =IF(Q59="","",_xlfn.CONCAT(UPPER(U59),", ",T59,". Disponível em <",R59,">. Acesso em ",TEXT(P59,"dd ""de"" mmmm ""de"" aaaa"),".")) -> PERDOMO, Óscar. Disponível em <https://www.plazapublica.com.gt/sites/default/files/2004_oscar_berger.pdf>. Acesso em 16 de dezembro de 2024.
... A64: Guatemala | B64: GTM | C64: 78 | D64: 1 | E64: 2020 | F64: Alejandro Eduardo Giammattei Falla | G64: President | H64: 9 | I64: 9 | J64: 9 | K64: 0 | L64: 9 | M64: =COUNTIF(H64:L64,"<>9") -> 1 | N64: =SUMIF(H64:L64,"<>9") -> 0 | O64: =IFERROR(ROUND(N64/M64,0),9) -> 0 | P64: 45642 | Q64: ESPANHOL | R64: https://www.plazapublica.com.gt/sites/default/files/2020_alejandro_giammattei.pdf | S64: GTM_ALEJANDRO_GIAMMATTEI_1.txt | T64: =_xlfn.TEXTBEFORE(F64," ") -> Alejandro | U64: =_xlfn.TEXTAFTER(F64," ",LEN(F64)-LEN(SUBSTITUTE(F64," ",""))) -> Falla | V64: =IF(Q64="","",_xlfn.CONCAT(UPPER(U64),", ",T64,". Disponível em <",R64,">. Acesso em ",TEXT(P64,"dd ""de"" mmmm ""de"" aaaa"),".")) -> FALLA, Alejandro. Disponível em <https://www.plazapublica.com.gt/sites/default/files/2020_alejandro_giammattei.pdf>. Acesso em 16 de dezembro de 2024.
A65: Haiti | B65: HTI | C65: 26 | D65: 3 | E65: 2006 | F65: René Garcia Préval | G65: President | H65: 9 | I65: 9 | J65: 9 | K65: 9 | L65: 9 | M65: =COUNTIF(H65:L65,"<>9") -> 0 | N65: =SUMIF(H65:L65,"<>9") -> 0 | O65: =IFERROR(ROUND(N65/M65,0),9) -> 9 | T65: =_xlfn.TEXTBEFORE(F65," ") -> René | U65: =_xlfn.TEXTAFTER(F65," ",LEN(F65)-LEN(SUBSTITUTE(F65," ",""))) -> Préval | V65: =IF(Q65="","",_xlfn.CONCAT(UPPER(U65),", ",T65,". Disponível em <",R65,">. Acesso em ",TEXT(P65,"dd ""de"" mmmm ""de"" aaaa"),"."))
A66: Haiti | B66: HTI | C66: 26 | D66: 1 | E66: 2011 | F66: Michel Martelly | G66: President | H66: 9 | I66: 9 | J66: 9 | K66: 9 | L66: 9 | M66: =COUNTIF(H66:L66,"<>9") -> 0 | N66: =SUMIF(H66:L66,"<>9") -> 0 | O66: =IFERROR(ROUND(N66/M66,0),9) -> 9 | T66: =_xlfn.TEXTBEFORE(F66," ") -> Michel | U66: =_xlfn.TEXTAFTER(F66," ",LEN(F66)-LEN(SUBSTITUTE(F66," ",""))) -> Martelly | V66: =IF(Q66="","",_xlfn.CONCAT(UPPER(U66),", ",T66,". Disponível em <",R66,">. Acesso em ",TEXT(P66,"dd ""de"" mmmm ""de"" aaaa"),"."))
A67: Haiti | B67: HTI | C67: 26 | D67: 1 | E67: 2016 | F67: Jocelerme Privert | G67: President | H67: 9 | I67: 9 | J67: 9 | K67: 9 | L67: 9 | M67: =COUNTIF(H67:L67,"<>9") -> 0 | N67: =SUMIF(H67:L67,"<>9") -> 0 | O67: =IFERROR(ROUND(N67/M67,0),9) -> 9 | T67: =_xlfn.TEXTBEFORE(F67," ") -> Jocelerme | U67: =_xlfn.TEXTAFTER(F67," ",LEN(F67)-LEN(SUBSTITUTE(F67," ",""))) -> Privert | V67: =IF(Q67="","",_xlfn.CONCAT(UPPER(U67),", ",T67,". Disponível em <",R67,">. Acesso em ",TEXT(P67,"dd ""de"" mmmm ""de"" aaaa"),"."))
...

Sheet TABELA DISSERTAÇÃO
B2: País | C2: Ano Discurso | D2: Presidente | E2: Funke, Shularick & Trebesch (2022) | F2: Kyle & Meyer (2020) | G2: Magud & Spilimbergo (2021) | H2: Hawkins et al. (2022) | I2: Edwards (2019)
B3: Argentina | C3: 2003 | D3: Néstor Carlos Kirchner Ostoic | E3: 1 | F3: 1 | G3: 1 | H3: 0 | I3: 1
B4: Argentina | C4: 2007 | D4: Cristina Fernández de Kirchner | E4: 1 | F4: 1 | G4: 1 | H4: 0 | I4: 1
B5: Argentina | C5: 2011 | D5: Cristina Fernández de Kirchner | E5: 1 | F5: 1 | G5: 1 | H5: 0 | I5: 1
B6: Argentina | C6: 2015 | D6: Mauricio Macri | E6: 0 | F6: 0 | G6: 0 | H6: 0 | I6: 0
B7: Argentina | C7: 2019 | D7: Alberto Fernández | E7: 0 | F7: 0 | G7: 0 | H7: 0 | I7: 9
B8: Bolívia | C8: 2005 | D8: Enrique Eduardo Rodríguez Veltzé | E8: 0 | F8: 0 | G8: 0 | H8: 0 | I8: 0
B9: Bolívia | C9: 2006 | D9: Juan Evo Morales Ayma | E9: 1 | F9: 1 | G9: 1 | H9: 1 | I9: 1
B10: Bolívia | C10: 2010 | D10: Juan Evo Morales Ayma | E10: 1 | F10: 1 | G10: 1 | H10: 1 | I10: 1
B11: Bolívia | C11: 2015 | D11: Juan Evo Morales Ayma | E11: 1 | F11: 1 | G11: 1 | H11: 1 | I11: 1
B12: Bolívia | C12: 2019 | D12: Jeanine Áñez Chávez | E12: 0 | F12: 0 | G12: 0 | H12: 0 | I12: 9
B13: Bolívia | C13: 2020 | D13: Luis Alberto Arce Catacora | E13: 0 | F13: 9 | G13: 9 | H13: 0 | I13: 9
B14: Brasil | C14: 2003 | D14: Luiz Inácio Lula da Silva | E14: 0 | F14: 0 | G14: 9 | H14: 0 | I14: 0
... B81: Venezuela | C81: 2019 | D81: Nicolás Maduro | E81: 1 | F81: 1 | G81: 1 | H81: 1 | I81: 9

Sheet TABELA FLAG POPULISMO
B2: País | C2: Ano Discurso | D2: Presidente | E2: Funke, Shularick & Trebesch (2022) | F2: Kyle & Meyer (2020) | G2: Magud & Spilimbergo (2021) | H2: Hawkins et al. (2022) | I2: Edwards (2019) | J2: QTD_OBS_VALIDA | K2: PONTUACAO_VALIDA | L2: Flag Populismo
B3: Argentina | C3: 2003 | D3: Néstor Carlos Kirchner Ostoic | E3: 1 | F3: 1 | G3: 1 | H3: 0 | I3: 1 | J3: =COUNTIF('TABELA DISSERTAÇÃO'!E3:I3,"<>9") -> 5 | K3: =SUMIF('TABELA DISSERTAÇÃO'!E3:I3,"<>9") -> 4 | L3: =IFERROR(ROUND(K3/J3,0),9) -> 1
B4: Argentina | C4: 2007 | D4: Cristina Fernández de Kirchner | E4: 1 | F4: 1 | G4: 1 | H4: 0 | I4: 1 | J4: =COUNTIF('TABELA DISSERTAÇÃO'!E4:I4,"<>9") -> 5 | K4: =SUMIF('TABELA DISSERTAÇÃO'!E4:I4,"<>9") -> 4 | L4: =IFERROR(ROUND(K4/J4,0),9) -> 1
B5: Argentina | C5: 2011 | D5: Cristina Fernández de Kirchner | E5: 1 | F5: 1 | G5: 1 | H5: 0 | I5: 1 | J5: =COUNTIF('TABELA DISSERTAÇÃO'!E5:I5,"<>9") -> 5 | K5: =SUMIF('TABELA DISSERTAÇÃO'!E5:I5,"<>9") -> 4 | L5: =IFERROR(ROUND(K5/J5,0),9) -> 1
B6: Argentina | C6: 2015 | D6: Mauricio Macri | E6: 0 | F6: 0 | G6: 0 | H6: 0 | I6: 0 | J6: =COUNTIF('TABELA DISSERTAÇÃO'!E6:I6,"<>9") -> 5 | K6: =SUMIF('TABELA DISSERTAÇÃO'!E6:I6,"<>9") -> 0 | L6: =IFERROR(ROUND(K6/J6,0),9) -> 0
B7: Argentina | C7: 2019 | D7: Alberto Fernández | E7: 0 | F7: 0 | G7: 0 | H7: 0 | I7: 9 | J7: =COUNTIF('TABELA DISSERTAÇÃO'!E7:I7,"<>9") -> 4 | K7: =SUMIF('TABELA DISSERTAÇÃO'!E7:I7,"<>9") -> 0 | L7: =IFERROR(ROUND(K7/J7,0),9) -> 0
B8: Bolívia | C8: 2005 | D8: Enrique Eduardo Rodríguez Veltzé | E8: 0 | F8: 0 | G8: 0 | H8: 0 | I8: 0 | J8: =COUNTIF('TABELA DISSERTAÇÃO'!E8:I8,"<>9") -> 5 | K8: =SUMIF('TABELA DISSERTAÇÃO'!E8:I8,"<>9") -> 0 | L8: =IFERROR(ROUND(K8/J8,0),9) -> 0
B9: Bolívia | C9: 2006 | D9: Juan Evo Morales Ayma | E9: 1 | F9: 1 | G9: 1 | H9: 1 | I9: 1 | J9: =COUNTIF('TABELA DISSERTAÇÃO'!E9:I9,"<>9") -> 5 | K9: =SUMIF('TABELA DISSERTAÇÃO'!E9:I9,"<>9") -> 5 | L9: =IFERROR(ROUND(K9/J9,0),9) -> 1
B10: Bolívia | C10: 2010 | D10: Juan Evo Morales Ayma | E10: 1 | F10: 1 | G10: 1 | H10: 1 | I10: 1 | J10: =COUNTIF('TABELA DISSERTAÇÃO'!E10:I10,"<>9") -> 5 | K10: =SUMIF('TABELA DISSERTAÇÃO'!E10:I10,"<>9") -> 5 | L10: =IFERROR(ROUND(K10/J10,0),9) -> 1
B11: Bolívia | C11: 2015 | D11: Juan Evo Morales Ayma | E11: 1 | F11: 1 | G11: 1 | H11: 1 | I11: 1 | J11: =COUNTIF('TABELA DISSERTAÇÃO'!E11:I11,"<>9") -> 5 | K11: =SUMIF('TABELA DISSERTAÇÃO'!E11:I11,"<>9") -> 5 | L11: =IFERROR(ROUND(K11/J11,0),9) -> 1
B12: Bolívia | C12: 2019 | D12: Jeanine Áñez Chávez | E12: 0 | F12: 0 | G12: 0 | H12: 0 | I12: 9 | J12: =COUNTIF('TABELA DISSERTAÇÃO'!E12:I12,"<>9") -> 4 | K12: =SUMIF('TABELA DISSERTAÇÃO'!E12:I12,"<>9") -> 0 | L12: =IFERROR(ROUND(K12/J12,0),9) -> 0
B13: Bolívia | C13: 2020 | D13: Luis Alberto Arce Catacora | E13: 0 | F13: 9 | G13: 9 | H13: 0 | I13: 9 | J13: =COUNTIF('TABELA DISSERTAÇÃO'!E13:I13,"<>9") -> 2 | K13: =SUMIF('TABELA DISSERTAÇÃO'!E13:I13,"<>9") -> 0 | L13: =IFERROR(ROUND(K13/J13,0),9) -> 0
B14: Brasil | C14: 2003 | D14: Luiz Inácio Lula da Silva | E14: 0 | F14: 0 | G14: 9 | H14: 0 | I14: 0 | J14: =COUNTIF('TABELA DISSERTAÇÃO'!E14:I14,"<>9") -> 4 | K14: =SUMIF('TABELA DISSERTAÇÃO'!E14:I14,"<>9") -> 0 | L14: =IFERROR(ROUND(K14/J14,0),9) -> 0
... B81: Venezuela | C81: 2019 | D81: Nicolás Maduro | E81: 1 | F81: 1 | G81: 1 | H81: 1 | I81: 9 | J81: =COUNTIF('TABELA DISSERTAÇÃO'!E81:I81,"<>9") -> 4 | K81: =SUMIF('TABELA DISSERTAÇÃO'!E81:I81,"<>9") -> 4 | L81: =IFERROR(ROUND(K81/J81,0),9) -> 1
